<?xml version="1.0" ?>
<!-- =================================================================================== -->
<!-- |    This document was autogenerated by xacro from kuka_iiwa.xacro                | -->
<!-- |    EDITING THIS FILE BY HAND IS NOT RECOMMENDED                                 | -->
<!-- =================================================================================== -->
<robot name="kuka_iiwa">
  <material name="silver">
    <color rgba="0.700 0.700 0.700 1.000"/>
  </material>
  <transmission name="base_link__link1_tran">
    <type>transmission_interface/SimpleTransmission</type>
    <joint name="base_link__link1">
      <hardwareInterface>hardware_interface/EffortJointInterface</hardwareInterface>
    </joint>
    <actuator name="base_link__link1_actr">
      <hardwareInterface>hardware_interface/EffortJointInterface</hardwareInterface>
      <mechanicalReduction>1</mechanicalReduction>
    </actuator>
  </transmission>
  <transmission name="link1__link2_tran">
    <type>transmission_interface/SimpleTransmission</type>
    <joint name="link1__link2">
      <hardwareInterface>hardware_interface/EffortJointInterface</hardwareInterface>
    </joint>
    <actuator name="link1__link2_actr">
      <hardwareInterface>hardware_interface/EffortJointInterface</hardwareInterface>
      <mechanicalReduction>1</mechanicalReduction>
    </actuator>
  </transmission>
  <transmission name="link2__link3_tran">
    <type>transmission_interface/SimpleTransmission</type>
    <joint name="link2__link3">
      <hardwareInterface>hardware_interface/EffortJointInterface</hardwareInterface>
    </joint>
    <actuator name="link2__link3_actr">
      <hardwareInterface>hardware_interface/EffortJointInterface</hardwareInterface>
      <mechanicalReduction>1</mechanicalReduction>
    </actuator>
  </transmission>
  <transmission name="link3__link4_tran">
    <type>transmission_interface/SimpleTransmission</type>
    <joint name="link3__link4">
      <hardwareInterface>hardware_interface/EffortJointInterface</hardwareInterface>
    </joint>
    <actuator name="link3__link4_actr">
      <hardwareInterface>hardware_interface/EffortJointInterface</hardwareInterface>
      <mechanicalReduction>1</mechanicalReduction>
    </actuator>
  </transmission>
  <transmission name="link4__link5_tran">
    <type>transmission_interface/SimpleTransmission</type>
    <joint name="link4__link5">
      <hardwareInterface>hardware_interface/EffortJointInterface</hardwareInterface>
    </joint>
    <actuator name="link4__link5_actr">
      <hardwareInterface>hardware_interface/EffortJointInterface</hardwareInterface>
      <mechanicalReduction>1</mechanicalReduction>
    </actuator>
  </transmission>
  <transmission name="link5__link6_tran">
    <type>transmission_interface/SimpleTransmission</type>
    <joint name="link5__link6">
      <hardwareInterface>hardware_interface/EffortJointInterface</hardwareInterface>
    </joint>
    <actuator name="link5__link6_actr">
      <hardwareInterface>hardware_interface/EffortJointInterface</hardwareInterface>
      <mechanicalReduction>1</mechanicalReduction>
    </actuator>
  </transmission>
  <transmission name="link6__link7_tran">
    <type>transmission_interface/SimpleTransmission</type>
    <joint name="link6__link7">
      <hardwareInterface>hardware_interface/EffortJointInterface</hardwareInterface>
    </joint>
    <actuator name="link6__link7_actr">
      <hardwareInterface>hardware_interface/EffortJointInterface</hardwareInterface>
      <mechanicalReduction>1</mechanicalReduction>
    </actuator>
  </transmission>
  <transmission name="link7__end_link_tran">
    <type>transmission_interface/SimpleTransmission</type>
    <joint name="link7__end_link">
      <hardwareInterface>hardware_interface/EffortJointInterface</hardwareInterface>
    </joint>
    <actuator name="link7__end_link_actr">
      <hardwareInterface>hardware_interface/EffortJointInterface</hardwareInterface>
      <mechanicalReduction>1</mechanicalReduction>
    </actuator>
  </transmission>
  <gazebo>
    <plugin filename="libgazebo_ros_control.so" name="control"/>
  </gazebo>
  <gazebo reference="base_link">
    <material>Gazebo/Silver</material>
    <mu1>0.2</mu1>
    <mu2>0.2</mu2>
    <selfCollide>true</selfCollide>
    <gravity>true</gravity>
  </gazebo>
  <gazebo reference="link1_1">
    <material>Gazebo/Silver</material>
    <mu1>0.2</mu1>
    <mu2>0.2</mu2>
    <selfCollide>true</selfCollide>
  </gazebo>
  <gazebo reference="link2_1">
    <material>Gazebo/Silver</material>
    <mu1>0.2</mu1>
    <mu2>0.2</mu2>
    <selfCollide>true</selfCollide>
  </gazebo>
  <gazebo reference="link3_1">
    <material>Gazebo/Silver</material>
    <mu1>0.2</mu1>
    <mu2>0.2</mu2>
    <selfCollide>true</selfCollide>
  </gazebo>
  <gazebo reference="link4_1">
    <material>Gazebo/Silver</material>
    <mu1>0.2</mu1>
    <mu2>0.2</mu2>
    <selfCollide>true</selfCollide>
  </gazebo>
  <gazebo reference="link5_1">
    <material>Gazebo/Silver</material>
    <mu1>0.2</mu1>
    <mu2>0.2</mu2>
    <selfCollide>true</selfCollide>
  </gazebo>
  <gazebo reference="link6_1">
    <material>Gazebo/Silver</material>
    <mu1>0.2</mu1>
    <mu2>0.2</mu2>
    <selfCollide>true</selfCollide>
  </gazebo>
  <gazebo reference="link7_1">
    <material>Gazebo/Silver</material>
    <mu1>0.2</mu1>
    <mu2>0.2</mu2>
    <selfCollide>true</selfCollide>
  </gazebo>
  <gazebo reference="end_link_1">
    <material>Gazebo/Silver</material>
    <mu1>0.2</mu1>
    <mu2>0.2</mu2>
    <selfCollide>true</selfCollide>
  </gazebo>
  <link name="base_link">
    <inertial>
      <origin rpy="0 0 0" xyz="-0.012820903814013492 0.0051115182659933955 0.0663962675807908"/>
      <mass value="42.988933075786555"/>
      <inertia ixx="0.190409" ixy="0.005311" ixz="0.0" iyy="0.262819" iyz="0.0" izz="0.242056"/>
    </inertial>
    <visual>
      <origin rpy="1.57 0 0" xyz="0 0.066396 0"/>
      <geometry>
        <mesh filename="package://kuka_iiwa_description/meshes/base_link.stl" scale="0.001 0.001 0.001"/>
      </geometry>
      <material name="silver"/>
    </visual>
    <collision>
      <origin rpy="0 0 0" xyz="0 0.066396 0"/>
      <geometry>
        <mesh filename="package://kuka_iiwa_description/meshes/base_link.stl" scale="0.001 0.001 0.001"/>
      </geometry>
    </collision>
  </link>
  <link name="link1_1">
    <inertial>
      <origin rpy="0 0 0" xyz="0.000513388107313499 0.13240338561657816 -0.03379169086163242"/>
      <mass value="32.25255782169743"/>
      <inertia ixx="0.258907" ixy="-0.000587" ixz="-3.5e-05" iyy="0.096765" iyz="0.038662" izz="0.261201"/>
    </inertial>
    <visual>
      <origin rpy="0 0 0" xyz="-0.0 -0.081105 -0.066396"/>
      <geometry>
        <mesh filename="package://kuka_iiwa_description/meshes/link1_1.stl" scale="0.001 0.001 0.001"/>
      </geometry>
      <material name="silver"/>
    </visual>
    <collision>
      <origin rpy="0 0 0" xyz="-0.0 -0.081105 -0.066396"/>
      <geometry>
        <mesh filename="package://kuka_iiwa_description/meshes/link1_1.stl" scale="0.001 0.001 0.001"/>
      </geometry>
    </collision>
  </link>
  <link name="link2_1">
    <inertial>
      <origin rpy="0 0 0" xyz="0.006790637041771156 0.05831151747503188 0.0520962364811052"/>
      <mass value="31.02033485964618"/>
      <inertia ixx="0.237289" ixy="-0.020857" ixz="0.005198" iyy="0.08923" iyz="0.037692" izz="0.238957"/>
    </inertial>
    <visual>
      <origin rpy="0 0 0" xyz="-0.000152 -0.293605 -0.056397"/>
      <geometry>
        <mesh filename="package://kuka_iiwa_description/meshes/link2_1.stl" scale="0.001 0.001 0.001"/>
      </geometry>
      <material name="silver"/>
    </visual>
    <collision>
      <origin rpy="0 0 0" xyz="-0.000152 -0.293605 -0.056397"/>
      <geometry>
        <mesh filename="package://kuka_iiwa_description/meshes/link2_1.stl" scale="0.001 0.001 0.001"/>
      </geometry>
    </collision>
  </link>
  <link name="link3_1">
    <inertial>
      <origin rpy="0 0 0" xyz="0.01839183607817021 0.1351938119333524 0.029831502276860905"/>
      <mass value="24.92491724179464"/>
      <inertia ixx="0.194363" ixy="-0.018427" ixz="-0.005218" iyy="0.062404" iyz="-0.038158" izz="0.186753"/>
    </inertial>
    <visual>
      <origin rpy="0 0 0" xyz="-0.025571 -0.486416 -0.066784"/>
      <geometry>
        <mesh filename="package://kuka_iiwa_description/meshes/link3_1.stl" scale="0.001 0.001 0.001"/>
      </geometry>
      <material name="silver"/>
    </visual>
    <collision>
      <origin rpy="0 0 0" xyz="-0.025571 -0.486416 -0.066784"/>
      <geometry>
        <mesh filename="package://kuka_iiwa_description/meshes/link3_1.stl" scale="0.001 0.001 0.001"/>
      </geometry>
    </collision>
  </link>
  <link name="link4_1">
    <inertial>
      <origin rpy="0 0 0" xyz="-0.0005772979947998233 0.06759793289135263 -0.04449035667683612"/>
      <mass value="21.504431474954778"/>
      <inertia ixx="0.135046" ixy="-0.000462" ixz="-0.00013" iyy="0.048366" iyz="-0.022671" izz="0.128521"/>
    </inertial>
    <visual>
      <origin rpy="0 0 0" xyz="-0.055377 -0.709916 -0.077734"/>
      <geometry>
        <mesh filename="package://kuka_iiwa_description/meshes/link4_1.stl" scale="0.001 0.001 0.001"/>
      </geometry>
      <material name="silver"/>
    </visual>
    <collision>
      <origin rpy="0 0 0" xyz="-0.055377 -0.709916 -0.077734"/>
      <geometry>
        <mesh filename="package://kuka_iiwa_description/meshes/link4_1.stl" scale="0.001 0.001 0.001"/>
      </geometry>
    </collision>
  </link>
  <link name="link5_1">
    <inertial>
      <origin rpy="0 0 0" xyz="2.8597556973354588e-05 0.08555414137410255 -0.021046066685368535"/>
      <mass value="13.295939170769604"/>
      <inertia ixx="0.079127" ixy="0.000187" ixz="-8.6e-05" iyy="0.034891" iyz="0.024126" izz="0.068511"/>
    </inertial>
    <visual>
      <origin rpy="0 0 0" xyz="-0.055471 -0.884457 -0.067931"/>
      <geometry>
        <mesh filename="package://kuka_iiwa_description/meshes/link5_1.stl" scale="0.001 0.001 0.001"/>
      </geometry>
      <material name="silver"/>
    </visual>
    <collision>
      <origin rpy="0 0 0" xyz="-0.055471 -0.884457 -0.067931"/>
      <geometry>
        <mesh filename="package://kuka_iiwa_description/meshes/link5_1.stl" scale="0.001 0.001 0.001"/>
      </geometry>
    </collision>
  </link>
  <link name="link6_1">
    <inertial>
      <origin rpy="0 0 0" xyz="0.0007170658959562148 0.0199124845020473 0.07105460912496495"/>
      <mass value="17.271121217368332"/>
      <inertia ixx="0.072656" ixy="1.9e-05" ixz="-1.6e-05" iyy="0.033094" iyz="0.001862" izz="0.07103"/>
    </inertial>
    <visual>
      <origin rpy="0 0 0" xyz="-0.055085 -1.110238 0.001864"/>
      <geometry>
        <mesh filename="package://kuka_iiwa_description/meshes/link6_1.stl" scale="0.001 0.001 0.001"/>
      </geometry>
      <material name="silver"/>
    </visual>
    <collision>
      <origin rpy="0 0 0" xyz="-0.055085 -1.110238 0.001864"/>
      <geometry>
        <mesh filename="package://kuka_iiwa_description/meshes/link6_1.stl" scale="0.001 0.001 0.001"/>
      </geometry>
    </collision>
  </link>
  <link name="link7_1">
    <inertial>
      <origin rpy="0 0 0" xyz="-5.067843141224465e-05 0.07271160190383918 0.00029667254133505794"/>
      <mass value="3.59003708727431"/>
      <inertia ixx="0.004896" ixy="6e-06" ixz="-0.0" iyy="0.003889" iyz="-5e-06" izz="0.004895"/>
    </inertial>
    <visual>
      <origin rpy="0 0 0" xyz="-0.055801 -1.181054 -0.069117"/>
      <geometry>
        <mesh filename="package://kuka_iiwa_description/meshes/link7_1.stl" scale="0.001 0.001 0.001"/>
      </geometry>
      <material name="silver"/>
    </visual>
    <collision>
      <origin rpy="0 0 0" xyz="-0.055801 -1.181054 -0.069117"/>
      <geometry>
        <mesh filename="package://kuka_iiwa_description/meshes/link7_1.stl" scale="0.001 0.001 0.001"/>
      </geometry>
    </collision>
  </link>
  <link name="end_link_1">
    <inertial>
      <origin rpy="0 0 0" xyz="-0.00016848294005620407 0.027313835797532215 9.298551248301812e-05"/>
      <mass value="2.4567876231793395"/>
      <inertia ixx="0.001756" ixy="3e-06" ixz="1e-06" iyy="0.002723" iyz="4e-06" izz="0.001778"/>
    </inertial>
    <visual>
      <origin rpy="0 0 0" xyz="-0.057084 -1.281054 -0.069383"/>
      <geometry>
        <mesh filename="package://kuka_iiwa_description/meshes/end_link_1.stl" scale="0.001 0.001 0.001"/>
      </geometry>
      <material name="silver"/>
    </visual>
    <collision>
      <origin rpy="0 0 0" xyz="-0.057084 -1.281054 -0.069383"/>
      <geometry>
        <mesh filename="package://kuka_iiwa_description/meshes/end_link_1.stl" scale="0.001 0.001 0.001"/>
      </geometry>
    </collision>
  </link>
  <joint name="base_link__link1" type="continuous">
    <origin rpy="1.57 0 0" xyz="0.0 0 0.081105"/>
    <parent link="base_link"/>
    <child link="link1_1"/>
    <axis xyz="0.0 1.0 0.0"/>
  </joint>
  <joint name="link1__link2" type="continuous">
    <origin rpy="0 0 0" xyz="0.000152 0.2125 -0.009999"/>
    <parent link="link1_1"/>
    <child link="link2_1"/>
    <axis xyz="0.0 0.0 1.0"/>
  </joint>
  <joint name="link2__link3" type="continuous">
    <origin rpy="0 0 0" xyz="0.025419 0.192811 0.010387"/>
    <parent link="link2_1"/>
    <child link="link3_1"/>
    <axis xyz="0.0 1.0 0.0"/>
  </joint>
  <joint name="link3__link4" type="continuous">
    <origin rpy="0 0 0" xyz="0.029806 0.2235 0.01095"/>
    <parent link="link3_1"/>
    <child link="link4_1"/>
    <axis xyz="0.0 0.0 -1.0"/>
  </joint>
  <joint name="link4__link5" type="continuous">
    <origin rpy="0 0 0" xyz="9.4e-05 0.174541 -0.009803"/>
    <parent link="link4_1"/>
    <child link="link5_1"/>
    <axis xyz="0.0 1.0 0.0"/>
  </joint>
  <joint name="link5__link6" type="continuous">
    <origin rpy="0 0 0" xyz="-0.000386 0.225781 -0.069795"/>
    <parent link="link5_1"/>
    <child link="link6_1"/>
    <axis xyz="0.0 0.0 1.0"/>
  </joint>
  <joint name="link6__link7" type="prismatic">
    <origin rpy="0 0 0" xyz="0.000716 0.070816 0.070981"/>
    <parent link="link6_1"/>
    <child link="link7_1"/>
    <axis xyz="0.0 1.0 0.0"/>
    <limit effort="100" lower="0.0" upper="0.0" velocity="100"/>
  </joint>
  <joint name="link7__end_link" type="continuous">
    <origin rpy="0 0 0" xyz="0.001283 0.1 0.000266"/>
    <parent link="link7_1"/>
    <child link="end_link_1"/>
    <axis xyz="0.0 -1.0 0.0"/>
  </joint>
</robot>

